<?xml version="1.0"?>
   <robot name="M.A.R.S_prototype1">


<link name="base_link">
    <visual>
        <geometry>
        <box size="1 1 1"/>
        </geometry>
    </visual>
</link>
<!--/////////////////////////////////////////////-->
<!-- BASE CYLINDER -->
<link name="base_cylinder">
    <visual>
    <geometry>
    <cylinder length="0.20" radius="0.09"/>
    </geometry>
    <origin rpy="0 0 0" xyz="0 0 0.10"/>
    </visual>
</link>

    <joint name="manipulator_to_base" type="revolute">
    <parent link="base_link"/>
    <child link="base_cylinder"/>
    <origin rpy="0 0 0" xyz="0 0 0.5"/>
    <axis xyz="0 0 1"/>
    <limit effort="300" velocity="1" lower="-3.14" upper="3.14"/>
    <dynamics damping="50" friction="1"/>
    </joint>
<!--/////////////////////////////////////////////////////////////////////////////////////////////////////////////////////////////////////////////////////////////////////////-->
<!-- LINK 2 -->
<link name="link_2">
    <visual>
        <geometry>
        <box size="0.34 0.154 0.056"/>
        </geometry>
        <origin rpy="0 1.57075 0" xyz="0.028 0 0.17"/>
    </visual>
    
    <collision>
        <geometry>
        <box size="0.35 0.164 0.066"/>
        </geometry>
    </collision>
</link>

    <joint name="base_cylinder_to_link2" type="revolute">
    <parent link="base_cylinder"/>
    <child link="link_2"/>
    <origin rpy="0 0 0" xyz="0.09 0 0.20"/>
    <axis xyz="1 0 0"/>
    <limit effort="300" velocity="1" lower="-1.57" upper="1.57"/>
    <dynamics damping="50" friction="1"/>
    </joint>
<!--///////////////////////////////////////////////////////////////////////////////////////////////////////////////////////////////////////////////////////////////////////////-->
<!-- LINK 3 -->
<link name="link_3">
    <visual>
        <geometry>
        <box size="0.30 0.1198 0.064"/>
        </geometry>
        <origin rpy="0 1.57075 0" xyz="-0.032 0 0.15"/>
    </visual>
    
    <collision>
        <geometry>
        <box size="0.31 0.1298 0.074"/>
        </geometry>
    </collision>
</link>

    <joint name="link_2_to_link_3" type="revolute">
    <parent link="link_2"/>
    <child link="link_3"/>
    <origin rpy="0 0 0" xyz="0 0 0.34"/>
    <axis xyz="1 0 0"/>
    <limit effort="30" velocity="1" lower="-1.57" upper="1.57"/>
    <dynamics damping="50" friction="1"/>
    </joint>
<!--///////////////////////////////////////////////////////////////////////////////////////////////////////////////////////////////////////////////////////////////////////////-->
<!-- LINK 4 -->
<link name="link_4">
    <visual>
        <geometry>
        <box size="0.09 0.0763 0.056"/>
        </geometry>
        <origin rpy="0 1.57075 0" xyz="0.028 0 0.045"/>
    </visual>
    
    <collision>
        <geometry>
        <box size="0.10 0.0863 0.066"/>
        </geometry>
    </collision>
</link>

    <joint name="link_3_to_link_4" type="revolute">
    <parent link="link_3"/>
    <child link="link_4"/>
    <origin rpy="0 0 0" xyz="0 0 0.30"/>
    <axis xyz="1 0 0"/>
    <limit effort="30" velocity="1" lower="-1.57" upper="1.57"/>
    <dynamics damping="50" friction="1"/>
    </joint>
<!--///////////////////////////////////////////////////////////////////////////////////////////////////////////////////////////////////////////////////////////////////////////-->
<!-- BASE CYLINDER -->
<link name="gripper_base">
    <visual>
    <geometry>
    <cylinder length="0.07425" radius="0.055"/>
    </geometry>
    <origin rpy="0 0 0" xyz="0 0 0.037125"/>
    </visual>

    <collision>
    <geometry>
    <cylinder length="0.07425" radius="0.055"/>
    </geometry>
    </collision>
    
</link>

    <joint name="link_4_to_gripper_base" type="revolute">
    <parent link="link_4"/>
    <child link="gripper_base"/>
    <origin rpy="0 0 0" xyz="0.028 0 0.09"/>
    <axis xyz="0 0 1"/>
    <limit effort="300" velocity="1" lower="-3.14" upper="3.14"/>
    <dynamics damping="50" friction="1"/>
    </joint>
<!--////////////////////////////////////////////////////////////////////////////////////////////////////////////////////////////////////////////////////////////////////////////-->
<link name="finger_base1">
    <visual>
        <geometry>
        <box size="0.062 0.03 0.03"/>
        </geometry>
        <origin rpy="0 1.57075 0" xyz="0 0 0.031"/>
    </visual>
    
    <collision>
        <geometry>
        <box size="0.062 0.03 0.03"/>
        </geometry>
    </collision>
</link>

    <joint name="gripper_base_to_finger_base1" type="revolute">
    <parent link="gripper_base"/>
    <child link="finger_base1"/>
    <origin rpy="0 0 0" xyz="0.055 0 0.07425"/>
    <axis xyz="0 1 0"/>
    <limit effort="30" velocity="1" lower="-0.0349066" upper="0.750492"/>
    <dynamics damping="50" friction="1"/>
    </joint>

<!--////////////////////////////////////////////////////////////////////////////////////////////////////////////////////////////////////////////////////////////////////////////-->
<link name="finger_top1">
    <visual>
        <geometry>
        <box size="0.052 0.028 0.016"/>
        </geometry>
        <origin rpy="0 1.57075 0" xyz="0 0 0.026"/>
    </visual>
    
    <collision>
        <geometry>
        <box size="0.062 0.03 0.03"/>
        </geometry>
    </collision>
</link>

    <joint name="finger_base1_to_finger_top1" type="revolute">
    <parent link="finger_base1"/>
    <child link="finger_top1"/>
    <origin rpy="0 0 0" xyz="0 0 0.062"/>
    <axis xyz="0 1 0"/>
    <limit effort="30" velocity="1" lower="0" upper="0.785398"/>
    <dynamics damping="50" friction="1"/>
    </joint>
<!--//////////////////////////////////////////////////////////////////////////////////////////////////////////////////////////////////////////////////////////////////////////-->
<link name="finger_base2">
    <visual>
        <geometry>
        <box size="0.062 0.03 0.03"/>
        </geometry>
        <origin rpy="0 1.57075 0" xyz="0 0 0.031"/>
    </visual>
    
    <collision>
        <geometry>
        <box size="0.062 0.03 0.03"/>
        </geometry>
    </collision>
</link>

    <joint name="gripper_base_to_finger_base2" type="revolute">
    <parent link="gripper_base"/>
    <child link="finger_base2"/>
    <origin rpy="0 0 0" xyz=" -0.0275 0.047631 0.07425"/>
    <axis xyz="0 1 0"/>
    <limit effort="30" velocity="1" lower="-0.0349066" upper="0.750492"/>
    <dynamics damping="50" friction="1"/>
    </joint>

<!--////////////////////////////////////////////////////////////////////////////////////////////////////////////////////////////////////////////////////////////////////////////-->
<link name="finger_top2">
    <visual>
        <geometry>
        <box size="0.052 0.028 0.016"/>
        </geometry>
        <origin rpy="0 1.57075 0" xyz="0 0 0.026"/>
    </visual>
    
    <collision>
        <geometry>
        <box size="0.062 0.03 0.03"/>
        </geometry>
    </collision>
</link>

    <joint name="finger_base2_to_finger_top2" type="revolute">
    <parent link="finger_base2"/>
    <child link="finger_top2"/>
    <origin rpy="0 0 0" xyz="0 0 0.062"/>
    <axis xyz="0 1 0"/>
    <limit effort="30" velocity="1" lower="0" upper="0.785398"/>
    <dynamics damping="50" friction="1"/>
    </joint>
<!--//////////////////////////////////////////////////////////////////////////////////////////////////////////////////////////////////////////////////////////////////////////-->
<link name="finger_base3">
    <visual>
        <geometry>
        <box size="0.062 0.03 0.03"/>
        </geometry>
        <origin rpy="0 1.57075 0" xyz="0 0 0.031"/>
    </visual>
    
    <collision>
        <geometry>
        <box size="0.062 0.03 0.03"/>
        </geometry>
    </collision>
</link>

    <joint name="gripper_base_to_finger_base3" type="revolute">
    <parent link="gripper_base"/>
    <child link="finger_base3"/>
    <origin rpy="0 0 0" xyz=" -0.0275 -0.047631 0.07425"/>
    <axis xyz="0 1 0"/>
    <limit effort="30" velocity="1" lower="-0.0349066" upper="0.750492"/>
    <dynamics damping="50" friction="1"/>
    </joint>

<!--////////////////////////////////////////////////////////////////////////////////////////////////////////////////////////////////////////////////////////////////////////////-->
<link name="finger_top3">
    <visual>
        <geometry>
        <box size="0.052 0.028 0.016"/>
        </geometry>
        <origin rpy="0 1.57075 0" xyz="0 0 0.026"/>
    </visual>
    
    <collision>
        <geometry>
        <box size="0.062 0.03 0.03"/>
        </geometry>
    </collision>
</link>

    <joint name="finger_base3_to_finger_top3" type="revolute">
    <parent link="finger_base3"/>
    <child link="finger_top3"/>
    <origin rpy="0 0 0" xyz="0 0 0.062"/>
    <axis xyz="0 1 0"/>
    <limit effort="30" velocity="1" lower="0" upper="0.785398"/>
    <dynamics damping="50" friction="1"/>
    </joint>
<!--//////////////////////////////////////////////////////////////////////////////////////////////////////////////////////////////////////////////////////////////////////////-->

</robot>