<?xml version="1.0" ?>
<!-- =================================================================================== -->
<!-- |    This document was autogenerated by xacro from gazebo_M.A.R.S_prototype_conv.urdf.xacro | -->
<!-- |    EDITING THIS FILE BY HAND IS NOT RECOMMENDED                                 | -->
<!-- =================================================================================== -->
<robot name="complete_M.A.R.S_prototype2" xmlns:xacro="http://www.ros.org/wiki/xacro">
  <!--<xacro:include filename="$(find urdf_package)/urdf/materials.xacro" />-->
  <!-- ////////////////////////////////////////////////////////////////////////////////////////////////////////////////////////////////////////////////////////////////////////-->
  <!--MATERIAL COLORS -->
  <material name="blue">
    <color rgba="0 0 1 1"/>
  </material>
  <material name="red">
    <color rgba="1 0 0 1"/>
  </material>
  <material name="pink">
    <color rgba="0.8 0 1 0.5"/>
  </material>
  <material name="white">
    <color rgba="1 1 1 1"/>
  </material>
  <material name="green">
    <color rgba="0 1 0 1"/>
  </material>
  <gazebo reference="base_link">
    <material>Gazebo/orange</material>
  </gazebo>
  <!--<xacro:macro name="box_inertial" params="x y z mass">
    <inertial>
      <mass value="${mass}" />
      <origin xyz="0 0 0" />
      <inertia ixx="${ 0.0833333 * mass * ( y * y + z * z )}" ixy="0.0" ixz="0.0"
        iyy="${0.0833333 * mass * ( x * x + z * z )}" iyz="0.0"
        izz="${0.0833333 * mass * (x * x + y * y)}" />
    </inertial>
</xacro:macro> -->
  <!--/////////////////////////////////////////////////////////////////////////////////////////////////////////////////////////////////////////////////////////////////////////-->
  <!-- MOBILE PLATFORM CHASSIS-->
  <link name="base_link">
    <visual>
      <geometry>
        <box size="0.6 0.45 0.50"/>
      </geometry>
      <origin rpy="0 0 0" xyz="0 0 0.275"/>
      <material name="blue"/>
    </visual>
    <collision>
      <geometry>
        <box size="0.6 0.45 0.50"/>
      </geometry>
      <origin rpy="0 0 0" xyz="0 0 0.275"/>
    </collision>
    <inertial>
      <mass value="5.0"/>
      <inertia ixx="0.18854166" ixy="0" ixz="0" iyy="0.25416666" iyz="0" izz="0.25416666"/>
      <origin rpy="0 0 0" xyz="0 0 0.275"/>
    </inertial>
  </link>
  <joint name="base_link_to_wheel1" type="continuous">
    <axis xyz="0 1 0"/>
    <origin rpy="0 0 0" xyz="0.17 0.255 0.075"/>
    <limit effort="100" velocity="100"/>
    <joint_properties damping="0.0" friction="0.0"/>
    <parent link="base_link"/>
    <child link="wheel1"/>
  </joint>
  <!--/////////////////////////////////////////////////////////////////////////////////////////////////////////////////////////////////////////////////////////////////////////-->
  <!--WHEEL_1-->
  <link name="wheel1">
    <visual>
      <geometry>
        <cylinder length="0.06" radius="0.075"/>
      </geometry>
      <origin rpy="0 1.57075 1.57075" xyz="0 0 0"/>
      <material name="white"/>
    </visual>
    <collision>
      <origin rpy="0 1.57075 1.57075" xyz="0 0 0"/>
      <geometry>
        <cylinder length="0.06" radius="0.075"/>
      </geometry>
    </collision>
    <inertial>
      <origin rpy="0 1.5707 1.5707" xyz="0 0 0"/>
      <mass value="0.4"/>
      <cylinder_inertia h="0.06" m="0.4" r="0.075"/>
      <inertia ixx="0.0006825" ixy="0.0" ixz="0.0" iyy="0.0006825" iyz="0.0" izz="0.00045"/>
    </inertial>
  </link>
  <!--/////////////////////////////////////////////////////////////////////////////////////////////////////////////////////////////////////////////////////////////////////////-->
  <!--WHEEL_2-->
  <link name="wheel2">
    <visual>
      <geometry>
        <cylinder length="0.06" radius="0.075"/>
      </geometry>
      <origin rpy="0 1.57075 1.57075" xyz="0 0 0"/>
      <material name="white"/>
    </visual>
    <collision>
      <origin rpy="0 1.57075 1.57075" xyz="0 0 0"/>
      <geometry>
        <cylinder length="0.06" radius="0.075"/>
      </geometry>
    </collision>
    <inertial>
      <origin rpy="0 1.5707 1.5707" xyz="0 0 0"/>
      <mass value="0.4"/>
      <cylinder_inertia h="0.06" m="0.4" r="0.075"/>
      <inertia ixx="0.0006825" ixy="0.0" ixz="0.0" iyy="0.0006825" iyz="0.0" izz="0.00045"/>
    </inertial>
  </link>
  <joint name="base_link_to_wheel2" type="continuous">
    <parent link="base_link"/>
    <child link="wheel2"/>
    <origin rpy="0 0 0" xyz="-0.17 0.255 0.075"/>
    <limit effort="100" velocity="100"/>
    <joint_properties damping="0.0" friction="0.0"/>
    <axis xyz="0 1 0"/>
  </joint>
  <!--/////////////////////////////////////////////////////////////////////////////////////////////////////////////////////////////////////////////////////////////////////////-->
  <!--WHEEL_3-->
  <link name="wheel3">
    <visual>
      <geometry>
        <cylinder length="0.06" radius="0.075"/>
      </geometry>
      <origin rpy="0 1.57075 1.57075" xyz="0 0 0"/>
      <material name="white"/>
    </visual>
    <collision>
      <origin rpy="0 1.57075 1.57075" xyz="0 0 0"/>
      <geometry>
        <cylinder length="0.06" radius="0.075"/>
      </geometry>
    </collision>
    <inertial>
      <origin rpy="0 1.5707 1.5707" xyz="0 0 0"/>
      <mass value="0.4"/>
      <cylinder_inertia h="0.06" m="0.4" r="0.075"/>
      <inertia ixx="0.0006825" ixy="0.0" ixz="0.0" iyy="0.0006825" iyz="0.0" izz="0.00045"/>
    </inertial>
  </link>
  <joint name="base_link_to_wheel3" type="continuous">
    <parent link="base_link"/>
    <child link="wheel3"/>
    <axis xyz="0 1 0"/>
    <limit effort="100" velocity="100"/>
    <joint_properties damping="0.0" friction="0.0"/>
    <origin xyz="0.17 -0.255 0.075"/>
  </joint>
  <!--/////////////////////////////////////////////////////////////////////////////////////////////////////////////////////////////////////////////////////////////////////////-->
  <!--WHEEL_4-->
  <link name="wheel4">
    <visual>
      <geometry>
        <cylinder length="0.06" radius="0.075"/>
      </geometry>
      <origin rpy="0 1.57075 1.57075" xyz="0 0 0"/>
      <material name="white"/>
    </visual>
    <collision>
      <origin rpy="0 1.57075 1.57075" xyz="0 0 0"/>
      <geometry>
        <cylinder length="0.06" radius="0.075"/>
      </geometry>
    </collision>
    <inertial>
      <origin rpy="0 1.5707 1.5707" xyz="0 0 0"/>
      <mass value="0.4"/>
      <cylinder_inertia h="0.06" m="0.4" r="0.075"/>
      <inertia ixx="0.0006825" ixy="0.0" ixz="0.0" iyy="0.0006825" iyz="0.0" izz="0.00045"/>
    </inertial>
  </link>
  <joint name="base_link_to_wheel4" type="continuous">
    <parent link="base_link"/>
    <child link="wheel4"/>
    <limit effort="100" velocity="100"/>
    <joint_properties damping="0.0" friction="0.0"/>
    <axis xyz="0 1 0"/>
    <origin xyz="-0.17 -0.255 0.075"/>
  </joint>
  <!--/////////////////////////////////////////////////////////////////////////////////////////////////////////////////////////////////////////////////////////////////////////-->
  <!--<link name="kinect">


    <visual>
      <geometry>
        <mesh filename="package://urdf_package/meshes/kinect.dae"/>
       </geometry>
      <origin rpy="0 0 0" xyz="0 0 0"/>
      
    </visual>
    </link>

     <joint name="base_link_to_kinect" type="fixed">
  <axis xyz="0 0 0"/> 
<origin rpy="0 0 1.5707" xyz="0.30 0 0.5631"/>
 
    <parent link="base_link"/> 
    <child link="kinect"/>
        
   
  </joint> -->
  <!--///////////////////////////////////////////////////////////////////////////////////////////////////////////////////////////////////////////////////////////////////////////-->
  <!-- MANIPULATOR-->
  <!-- BASE CYLINDER -->
  <link name="base_cylinder">
    <visual>
      <geometry>
        <cylinder length="0.20" radius="0.09"/>
      </geometry>
      <origin rpy="0 0 0" xyz="0 0 0.10"/>
      <material name="blue"/>
    </visual>
    <collision>
      <geometry>
        <cylinder length="0.21" radius="0.10"/>
      </geometry>
      <origin rpy="0 0 0" xyz="0 0 0.10"/>
    </collision>
    <inertial>
      <mass value="3"/>
      <origin xyz="0 0 0.1"/>
      <inertia ixx="0.01607499357" ixy="0.0" ixz="0.0" iyy="0.01607499357" iyz="0.0" izz="0.01215"/>
    </inertial>
  </link>
  <joint name="manipulator_to_base_link" type="revolute">
    <parent link="base_link"/>
    <child link="base_cylinder"/>
    <origin rpy="0 0 0" xyz="0 0 0.5"/>
    <axis xyz="0 0 1"/>
    <limit effort="30" lower="-3.14" upper="3.14" velocity="1"/>
    <dynamics damping="50" friction="1"/>
  </joint>
  <!--/////////////////////////////////////////////////////////////////////////////////////////////////////////////////////////////////////////////////////////////////////////-->
  <!-- LINK 2 -->
  <link name="link_2">
    <visual>
      <geometry>
        <box size="0.34 0.154 0.056"/>
      </geometry>
      <origin rpy="0 1.57075 0" xyz="0.028 0 0.17"/>
    </visual>
    <collision>
      <geometry>
        <box size="0.35 0.164 0.066"/>
      </geometry>
      <origin rpy="0 1.57075 0" xyz="0.028 0 0.17"/>
    </collision>
    <!-- PHYSICAL PROPERTIES -->
    <!--<box_inertial x="0.34" y="0.154" z="0.056" mass="1.153"/> -->
    <inertial>
      <mass value="1.153"/>
      <inertia ixx="0.01338594" ixy="0.0" ixz="0.0" iyy="0.01140855" iyz="0.0" izz="0.00258002"/>
      <origin rpy="0 0 0" xyz="0.033 0 0.17"/>
    </inertial>
  </link>
  <joint name="base_cylinder_to_link2" type="revolute">
    <parent link="base_cylinder"/>
    <child link="link_2"/>
    <origin rpy="0 0 0" xyz="0.09 0 0.20"/>
    <axis xyz="1 0 0"/>
    <limit effort="25" lower="-1.57" upper="1.57" velocity="0.2094"/>
    <dynamics damping="50" friction="1"/>
  </joint>
  <!--///////////////////////////////////////////////////////////////////////////////////////////////////////////////////////////////////////////////////////////////////////////-->
  <!-- LINK 3 -->
  <link name="link_3">
    <visual>
      <geometry>
        <box size="0.30 0.1198 0.064"/>
      </geometry>
      <origin rpy="0 1.57075 0" xyz="-0.032 0 0.15"/>
      <material name="green"/>
    </visual>
    <collision>
      <geometry>
        <box size="0.31 0.1298 0.074"/>
      </geometry>
      <origin rpy="0 1.57075 0" xyz="-0.032 0 0.15"/>
    </collision>
    <!-- PHYSICAL PROPERTIES -->
    <!--<xacro:box_inertial x="0.30" y="0.1198" z="0.064" mass="0.744"/> -->
    <inertial>
      <mass value="0.744"/>
      <inertia ixx="0.00646982" ixy="0.0" ixz="0.0" iyy="0.005833952" iyz="0.0" izz="0.00114377"/>
      <origin rpy="0 0 0" xyz="-0.032 0 0.15"/>
    </inertial>
  </link>
  <joint name="link_2_to_link_3" type="revolute">
    <parent link="link_2"/>
    <child link="link_3"/>
    <origin rpy="0 0 0" xyz="0 0 0.34"/>
    <axis xyz="1 0 0"/>
    <limit effort="15" lower="-1.57" upper="1.57" velocity="5.2359"/>
    <dynamics damping="50" friction="1"/>
  </joint>
  <!--///////////////////////////////////////////////////////////////////////////////////////////////////////////////////////////////////////////////////////////////////////////-->
  <!-- LINK 4 -->
  <link name="link_4">
    <visual>
      <geometry>
        <box size="0.09 0.0763 0.056"/>
      </geometry>
      <origin rpy="0 1.57075 0" xyz="0.028 0 0.045"/>
      <material name="blue"/>
    </visual>
    <collision>
      <geometry>
        <box size="0.10 0.0863 0.066"/>
      </geometry>
      <origin rpy="0 1.57075 0" xyz="0.028 0 0.045"/>
    </collision>
    <!-- PHYSICAL PROPERTIES -->
    <!--<xacro:box_inertial x="0.09" y="0.0763" z="0.056" mass="0.674"/> -->
    <inertial>
      <mass value="0.674"/>
      <inertia ixx="0.00078193" ixy="0.0" ixz="0.0" iyy="0.00063108" iyz="0.0" izz="0.00050312"/>
      <origin rpy="0 0 0" xyz="0.028 0 0.045"/>
    </inertial>
  </link>
  <joint name="link_3_to_link_4" type="revolute">
    <parent link="link_3"/>
    <child link="link_4"/>
    <origin rpy="0 0 0" xyz="0 0 0.30"/>
    <axis xyz="1 0 0"/>
    <limit effort="5" lower="-1.57" upper="1.57" velocity="3.14"/>
    <dynamics damping="50" friction="1"/>
  </joint>
  <!--///////////////////////////////////////////////////////////////////////////////////////////////////////////////////////////////////////////////////////////////////////////-->
  <!-- GRIPPER BASE -->
  <link name="gripper_base">
    <visual>
      <geometry>
        <cylinder length="0.07425" radius="0.055"/>
      </geometry>
      <origin rpy="0 0 0" xyz="0 0 0.037125"/>
      <material name="green"/>
    </visual>
    <collision>
      <geometry>
        <cylinder length="0.07425" radius="0.055"/>
      </geometry>
      <origin rpy="0 0 0" xyz="0 0 0.037125"/>
    </collision>
    <!-- PHYSICAL PROPERTIES -->
    <inertial>
      <mass value="0.3"/>
      <origin xyz="0 0 0.03712"/>
      <inertia ixx="0.000364701416619" ixy="0.0" ixz="0.0" iyy="0.000364701416619" iyz="0.0" izz="0.00045375"/>
    </inertial>
    <!--<inertial>
    <mass value="3"/>
    <inertia ixx="3.571e-04" ixy="1.133e-08" ixz="-6.324e-08" iyy="1.133e" iyz="0.0" izz="0.2"/>
    </inertial>  -->
  </link>
  <joint name="link_4_to_gripper_base" type="revolute">
    <parent link="link_4"/>
    <child link="gripper_base"/>
    <origin rpy="0 0 0" xyz="0.028 0 0.09"/>
    <axis xyz="0 0 1"/>
    <limit effort="5" lower="-3.14" upper="3.14" velocity="3.14"/>
    <dynamics damping="50" friction="1"/>
  </joint>
</robot>
